/home/doug/virtenvs/prmzo/local/lib/python2.7/site-packages/six.py:808: RemovedInDjango110Warning: SubfieldBase has been deprecated. Use Field.from_db_value instead.
  return meta(name, bases, d)

.FFF..FFFFFFFFF
======================================================================
FAIL: test_changeBusinessUser (core.tests.UserTestCase)
----------------------------------------------------------------------
Traceback (most recent call last):
  File "/media/doug/USB20FD/ProMazo2/promazo/core/tests.py", line 125, in test_changeBusinessUser
    self.assertContains(resp,'Changed14')
  File "/home/doug/virtenvs/prmzo/local/lib/python2.7/site-packages/django/test/testcases.py", line 390, in assertContains
    response, text, status_code, msg_prefix, html)
  File "/home/doug/virtenvs/prmzo/local/lib/python2.7/site-packages/django/test/testcases.py", line 360, in _assert_contains
    " (expected %d)" % (response.status_code, status_code))
AssertionError: Couldn't retrieve content: Response code was 405 (expected 200)

======================================================================
FAIL: test_deleteDocument (core.tests.UserTestCase)
----------------------------------------------------------------------
Traceback (most recent call last):
  File "/media/doug/USB20FD/ProMazo2/promazo/core/tests.py", line 139, in test_deleteDocument
    self.assertEqual(resp.status_code,204)
AssertionError: 400 != 204

======================================================================
FAIL: test_failedModify (core.tests.UserTestCase)
----------------------------------------------------------------------
Traceback (most recent call last):
  File "/media/doug/USB20FD/ProMazo2/promazo/core/tests.py", line 120, in test_failedModify
    self.assertEqual(resp.status_code,401)
AssertionError: 403 != 401

======================================================================
FAIL: test_listDocuments (core.tests.UserTestCase)
----------------------------------------------------------------------
Traceback (most recent call last):
  File "/media/doug/USB20FD/ProMazo2/promazo/core/tests.py", line 128, in test_listDocuments
    self.assertContains(resp,'document1')
  File "/home/doug/virtenvs/prmzo/local/lib/python2.7/site-packages/django/test/testcases.py", line 398, in assertContains
    msg_prefix + "Couldn't find %s in response" % text_repr)
AssertionError: Couldn't find 'document1' in response

======================================================================
FAIL: test_login (core.tests.UserTestCase)
----------------------------------------------------------------------
Traceback (most recent call last):
  File "/media/doug/USB20FD/ProMazo2/promazo/core/tests.py", line 100, in test_login
    self.assertContains(resp,'user_type')
  File "/home/doug/virtenvs/prmzo/local/lib/python2.7/site-packages/django/test/testcases.py", line 390, in assertContains
    response, text, status_code, msg_prefix, html)
  File "/home/doug/virtenvs/prmzo/local/lib/python2.7/site-packages/django/test/testcases.py", line 360, in _assert_contains
    " (expected %d)" % (response.status_code, status_code))
AssertionError: Couldn't retrieve content: Response code was 401 (expected 200)

======================================================================
FAIL: test_logout (core.tests.UserTestCase)
----------------------------------------------------------------------
Traceback (most recent call last):
  File "/media/doug/USB20FD/ProMazo2/promazo/core/tests.py", line 109, in test_logout
    self.assertContains(resp,'Success')
  File "/home/doug/virtenvs/prmzo/local/lib/python2.7/site-packages/django/test/testcases.py", line 390, in assertContains
    response, text, status_code, msg_prefix, html)
  File "/home/doug/virtenvs/prmzo/local/lib/python2.7/site-packages/django/test/testcases.py", line 360, in _assert_contains
    " (expected %d)" % (response.status_code, status_code))
AssertionError: Couldn't retrieve content: Response code was 204 (expected 200)

======================================================================
FAIL: test_modifyDetails (core.tests.UserTestCase)
----------------------------------------------------------------------
Traceback (most recent call last):
  File "/media/doug/USB20FD/ProMazo2/promazo/core/tests.py", line 114, in test_modifyDetails
    self.assertContains(resp,'Changed12')
  File "/home/doug/virtenvs/prmzo/local/lib/python2.7/site-packages/django/test/testcases.py", line 390, in assertContains
    response, text, status_code, msg_prefix, html)
  File "/home/doug/virtenvs/prmzo/local/lib/python2.7/site-packages/django/test/testcases.py", line 360, in _assert_contains
    " (expected %d)" % (response.status_code, status_code))
AssertionError: Couldn't retrieve content: Response code was 405 (expected 200)

======================================================================
FAIL: test_registerInvalidStudent (core.tests.UserTestCase)
----------------------------------------------------------------------
Traceback (most recent call last):
  File "/media/doug/USB20FD/ProMazo2/promazo/core/tests.py", line 94, in test_registerInvalidStudent
    self.assertContains(resp, 'Invalid University email address')
  File "/home/doug/virtenvs/prmzo/local/lib/python2.7/site-packages/django/test/testcases.py", line 390, in assertContains
    response, text, status_code, msg_prefix, html)
  File "/home/doug/virtenvs/prmzo/local/lib/python2.7/site-packages/django/test/testcases.py", line 360, in _assert_contains
    " (expected %d)" % (response.status_code, status_code))
AssertionError: Couldn't retrieve content: Response code was 405 (expected 200)

======================================================================
FAIL: test_registerNewStudent (core.tests.UserTestCase)
----------------------------------------------------------------------
Traceback (most recent call last):
  File "/media/doug/USB20FD/ProMazo2/promazo/core/tests.py", line 88, in test_registerNewStudent
    self.assertContains(resp, 'Success')
  File "/home/doug/virtenvs/prmzo/local/lib/python2.7/site-packages/django/test/testcases.py", line 390, in assertContains
    response, text, status_code, msg_prefix, html)
  File "/home/doug/virtenvs/prmzo/local/lib/python2.7/site-packages/django/test/testcases.py", line 360, in _assert_contains
    " (expected %d)" % (response.status_code, status_code))
AssertionError: Couldn't retrieve content: Response code was 405 (expected 200)

======================================================================
FAIL: test_resetPasswordInvalidEmail (core.tests.UserTestCase)
----------------------------------------------------------------------
Traceback (most recent call last):
  File "/media/doug/USB20FD/ProMazo2/promazo/core/tests.py", line 81, in test_resetPasswordInvalidEmail
    self.assertContains(resp,'Sorry, Email not found',status_code=401)
  File "/home/doug/virtenvs/prmzo/local/lib/python2.7/site-packages/django/test/testcases.py", line 390, in assertContains
    response, text, status_code, msg_prefix, html)
  File "/home/doug/virtenvs/prmzo/local/lib/python2.7/site-packages/django/test/testcases.py", line 360, in _assert_contains
    " (expected %d)" % (response.status_code, status_code))
AssertionError: Couldn't retrieve content: Response code was 404 (expected 401)

======================================================================
FAIL: test_resetPasswordUnauthenticated (core.tests.UserTestCase)
----------------------------------------------------------------------
Traceback (most recent call last):
  File "/media/doug/USB20FD/ProMazo2/promazo/core/tests.py", line 76, in test_resetPasswordUnauthenticated
    self.assertContains(resp,'Authentication credentials were not provided.')
  File "/home/doug/virtenvs/prmzo/local/lib/python2.7/site-packages/django/test/testcases.py", line 390, in assertContains
    response, text, status_code, msg_prefix, html)
  File "/home/doug/virtenvs/prmzo/local/lib/python2.7/site-packages/django/test/testcases.py", line 360, in _assert_contains
    " (expected %d)" % (response.status_code, status_code))
AssertionError: Couldn't retrieve content: Response code was 404 (expected 200)

======================================================================
FAIL: test_resetPaswordAuthenticated (core.tests.UserTestCase)
----------------------------------------------------------------------
Traceback (most recent call last):
  File "/media/doug/USB20FD/ProMazo2/promazo/core/tests.py", line 69, in test_resetPaswordAuthenticated
    self.assertContains(resp,'password reset')
  File "/home/doug/virtenvs/prmzo/local/lib/python2.7/site-packages/django/test/testcases.py", line 390, in assertContains
    response, text, status_code, msg_prefix, html)
  File "/home/doug/virtenvs/prmzo/local/lib/python2.7/site-packages/django/test/testcases.py", line 360, in _assert_contains
    " (expected %d)" % (response.status_code, status_code))
AssertionError: Couldn't retrieve content: Response code was 405 (expected 200)

----------------------------------------------------------------------
Ran 15 tests in 2.040s

FAILED (failures=12)
